Workbook
Name UPDATE: 'Data Sheet'!$E$1

Sheet DCF>

Sheet DCF
B2: ="DCF Vatuation - "&'Data Sheet'!B1 -> DCF Vatuation - ASIAN PAINTS LTD
B7: Calculation of PV of FCFF | F7: ='Raw FS'!N2 -> 45717 | G7: =F7+366 -> 46083 | H7: =G7+366 -> 46449 | I7: =H7+366 -> 46815 | J7: =I7+366 -> 47181 | K7: =J7+366 -> 47547
B9: EBIT | F9: ='Data Sheet'!K33-'Data Sheet'!K26 -> 5287.61 | G9: =F9*(1+$E$19) -> 6535.7563 | H9: =G9*(1+$E$19) -> 8078.529 | I9: =H9*(1+$E$19) -> 9985.4749 | J9: =I9*(1+$E$19) -> 12342.558 | K9: =J9*(1+$E$19) -> 15256.032 | L9: -
B10: Tax Rate | F10: 0.25 | G10: =F10 -> 0.25 | H10: =G10 -> 0.25 | I10: =H10 -> 0.25 | J10: =I10 -> 0.25 | K10: =J10 -> 0.25 | L10: -
B11: EBIT(1-T) | F11: =F9*(1-F10) -> 3965.7075 | G11: =G9*(1-G10) -> 4901.8172 | H11: =H9*(1-H10) -> 6058.8968 | I11: =I9*(1-I10) -> 7489.1062 | J11: =J9*(1-J10) -> 9256.9182 | K11: =K9*(1-K10) -> 11442.024 | L11: -
B12: Less: Reinvestment | F12: ='Intrisic Growth'!K55 -> 0.48354676 | G12: =F12+(($K$12-F12))/4 -> 0.49021043 | H12: =G12+(($K$12-G12))/4 -> 0.49520818 | I12: =H12+(($K$12-H12))/4 -> 0.49895649 | J12: =I12+(($K$12-I12))/4 -> 0.50176772 | K12: ='Intrisic Growth'!K58 -> 0.51020143 | L12: -
B13: Free Cash Flow to Firm | F13: =F11*(1-F12) -> 2048.1025 | G13: =G11*(1-G12) -> 2498.8953 | H13: =H11*(1-H12) -> 3058.4815 | I13: =I11*(1-I12) -> 3752.3681 | J13: =J11*(1-J12) -> 4612.0954 | K13: =K11*(1-K12) -> 5604.2871 | L13: -
B14: Mid Convertion | G14: 0.5 | H14: =G14+1 -> 1.5 | I14: =H14+1 -> 2.5 | J14: =I14+1 -> 3.5 | K14: =J14+1 -> 4.5 | L14: -
B15: Discounting Factor | G15: =1/(1+$E$21)^G14 -> 0.94512154 | H15: =1/(1+$E$21)^H14 -> 0.84423427 | I15: =1/(1+$E$21)^I14 -> 0.75411625 | J15: =1/(1+$E$21)^J14 -> 0.6736179 | K15: =1/(1+$E$21)^K14 -> 0.60171237 | L15: -
L16: -
B17: PV of FCFF | G17: =G13*G15 -> 2361.7598 | H17: =H13*H15 -> 2582.0749 | I17: =I13*I15 -> 2829.7217 | J17: =J13*J15 -> 3106.79 | K17: =K13*K15 -> 3372.1689 | L17: -
B19: Expected Growth | E19: ='Intrisic Growth'!K68 -> 0.23605113
B20: Terminal Growth | E20: 0.04
B21: WACC | E21: ='WACC(Geometric)'!J46 -> 0.1195015
B23: Calculation of Terminal Value
B25: FCFF (n+1) | E25: =K13*(1+E19) -> 6927.1854
B26: WACC | E26: =E21 -> 0.1195015
B27: Terminal Growth Rate | E27: =E20 -> 0.04
B29: Terminal Value | E29: =E25/(E26-E27) -> 87132.763
B31: Calculation of Equity Value | G31: Sensitivity Analysis
B33: PV of FCFF | E33: =SUM(G17:K17) -> 14252.515 | G33: =E35 -> 101385.28 | H33: 0.105 | I33: 0.11 | J33: 0.115 | K33: 0.1195 | L33: 0.125
B34: Terminal Value | E34: =E29 -> 87132.763 | G34: 0.035 | H34: 113212.31 | I34: 106614.99 | J34: 100842.33 | K34: 96231.041 | L34: 91221.243
B35: Value of Operating Assets | E35: =SUM(E33:E34) -> 101385.28 | G35: 0.04 | H35: 120824.6 | I35: 113212.31 | J35: 106614.99 | K35: 101386.92 | L35: 95748.815
G36: 0.0433 | H36: 126524.56 | I36: 118108.37 | J36: 110865.98 | K36: 105160.46 | L36: 99040.587
B37: Add: Cash | E37: ='Data Sheet'!K69 -> 781.98 | G37: 0.045 | H37: 129705.61 | I37: 120824.6 | J37: 113212.31 | K37: 107234.87 | L37: 100842.33
B38: Less: Debt | E38: =SUM('Raw FS'!N7:N8) -> 864 | G38: 0.05 | H38: 140201.34 | I38: 129705.61 | J38: 120824.6 | K38: 113924.25 | L38: 106614.99
B39: Value of Equity | E39: =E35+E37-E38 -> 101303.26
B40: No of Share | E40: ='Data Sheet'!B6 -> 95.961577
B42: Equity Value per Share | E42: =E39/E40 -> 1055.6648
B44: Share Price | E44: 2207
B45: Discount/Premium | E45: =E44/E42 -> 2.0906258
B47: Stock is overvalued | E47: =(E44-E42)/E42 -> 1.0906258

Sheet WACC(Geometric)
B4: Asian Paints
B7: Wieghhted Average Cost of Capital (WACC)
B9: All Figures are in unless stated otherwise
B11: Peers Comps
G12: Debt / | H12: Debt / | I12: Levered | J12: Unleverd
B13: Name OF the Com | C13: Country | D13: Total Debt | E13: Total Equity | F13: Tax Rate 1 | G13: Equity | H13: Capital | I13: Beta 2 | J13: Beta 3
B15: Asian Paints | C15: India | D15: 3557.09 | E15: 203411.79 | F15: 0.3 | G15: =D15/E15 -> 0.017487138 | H15: =D15/(D15+E15) -> 0.017186593 | I15: ='WACC(Arithmetic)'!I15 -> 1.2350587 | J15: =I15/(1+(1-F15)*G15) -> 1.2201231
B16: Berger Paints | C16: India | D16: 697.33 | E16: 48348.31 | F16: 0.3 | G16: =D16/E16 -> 0.014423048 | H16: =D16/(D16+E16) -> 0.014217981 | I16: ='WACC(Arithmetic)'!I16 -> 1.1107726 | J16: =I16/(1+(1-F16)*G16) -> 1.0996702
B17: Kansai Nerolac | C17: India | D17: 275.42 | E17: 13787.62 | F17: 0.3 | G17: =D17/E17 -> 0.019975891 | H17: =D17/(D17+E17) -> 0.01958467 | I17: ='WACC(Arithmetic)'!I17 -> 0.92242955 | J17: =I17/(1+(1-F17)*G17) -> 0.90970898
B18: Indigo Paints | C18: India | D18: 17.2 | E18: 3484.14 | F18: 0.3 | G18: =D18/E18 -> 0.0049366558 | H18: =D18/(D18+E18) -> 0.004912405 | I18: ='WACC(Arithmetic)'!I18 -> 1.0513967 | J18: =I18/(1+(1-F18)*G18) -> 1.0477759
E20: Average | F20: =AVERAGE(F15:F18) -> 0.3 | G20: =AVERAGE(G16:G18) -> 0.013111865 | H20: =AVERAGE(H15:H18) -> 0.013975413 | I20: =AVERAGE(I16:I18) -> 1.0281996 | J20: =AVERAGE(J16:J18) -> 1.0190517
E21: Median | F21: =MEDIAN(F15:F18) -> 0.3 | G21: =MEDIAN(G15:G18) -> 0.015955093 | H21: =MEDIAN(H15:H18) -> 0.015702287 | I21: =MEDIAN(I15:I18) -> 1.0810846 | J21: =MEDIAN(J15:J18) -> 1.0737231
B24: Cost of DEBT | G24: Cost of Equity
B26: Pre-Tax Cost of Debt | E26: =227/3557.09 -> 0.063816209 | G26: Risk Free Rate | J26: 0.0684
B27: Tax Rate | E27: =F15 -> 0.3 | G27: Equity Risk Premium | J27: ='Market Return'!F8-'WACC(Geometric)'!J26 -> 0.048103341
B28: Post Tax Cost of Debt | E28: =E26*(1-E27) -> 0.044671347 | G28: Levered Beta 4 | J28: =J36 -> 1.0843759
G29: Cost of Equity | J29: =J26+J27*J28 -> 0.12056211
B31: Capital Structure | G31: Levered Beta
D33: Current | E33: Target | G33: Comps Median Unlevered Beta | J33: =J21 -> 1.0737231
B34: Total Debt | C34: =D15 -> 3557.09 | D34: =C34/C36 -> 0.017186593 | E34: =H20 -> 0.013975413 | G34: Target Debt / Equity | J34: =E38 -> 0.014173493
B35: Market Capitalization | C35: =E15 -> 203411.79 | D35: =C35/C36 -> 0.98281341 | E35: =E36-E34 -> 0.98602459 | G35: Tax Rate | J35: =E27 -> 0.3
B36: Total Capital | C36: =SUM(C34:C35) -> 206968.88 | D36: =SUM(D34:D35) -> 1 | E36: =D36 -> 1 | G36: Levered Beta | J36: =J33*(1+(1-J35)*J34) -> 1.0843759
B38: Debt / Equity | D38: =D34/D35 -> 0.017487138 | E38: =E34/E35 -> 0.014173493 | G38: Weight Average Cost of Capital
B40: Notes: | G40: Cost of Equity | J40: =J29 -> 0.12056211
B41: 1. Tax Rate considered as Marginal Tax Rate for the country | G41: Equity Weight | J41: =E35 -> 0.98602459
B42: 2. Levered beta is based on 5 year monthly data
B43: 3. Unlevered Beta = Levered Beta/(1+(1-tax rate)*Debt/Equity) | G43: Cost of Debt | J43: =E28 -> 0.044671347
B44: 4. Levered Beta = Unlevered Beta *(1+(1-Tax Rate)*Debt/Equity) | G44: Debt Weight | J44: =E34 -> 0.013975413
G46: WACC | J46: =(J40*J41)+(J43*J44) -> 0.1195015

Sheet Financials>

Sheet Historical FS 
B2: ="Historical Financial Statement - "&'Data Sheet'!B1 -> Historical Financial Statement - ASIAN PAINTS LTD
B3: Years | C3: ='Data Sheet'!B16 -> 42460 | D3: ='Data Sheet'!C16 -> 42825 | E3: ='Data Sheet'!D16 -> 43190 | F3: ='Data Sheet'!E16 -> 43555 | G3: ='Data Sheet'!F16 -> 43921 | H3: ='Data Sheet'!G16 -> 44286 | I3: ='Data Sheet'!H16 -> 44651 | J3: ='Data Sheet'!I16 -> 45016 | ... L3: ='Data Sheet'!K16 -> 45747 | M3: LTM
A5: # | B5: Income Statement
B6: Sales | C6: =IFERROR('Data Sheet'!B17,0) -> 14271.49 | D6: =IFERROR('Data Sheet'!C17,0) -> 15061.99 | E6: =IFERROR('Data Sheet'!D17,0) -> 16824.55 | F6: =IFERROR('Data Sheet'!E17,0) -> 19240.13 | G6: =IFERROR('Data Sheet'!F17,0) -> 20211.25 | H6: =IFERROR('Data Sheet'!G17,0) -> 21712.79 | I6: =IFERROR('Data Sheet'!H17,0) -> 29101.28 | J6: =IFERROR('Data Sheet'!I17,0) -> 34488.59 | ... L6: =IFERROR('Data Sheet'!K17,0) -> 33905.62 | M6: =IFERROR(SUM('Data Sheet'!H42:K42),0) -> 34695.75
B7: Sales Growth | D7: =D6/C6-1 -> 0.055390152 | E7: =E6/D6-1 -> 0.11702039 | F7: =F6/E6-1 -> 0.14357472 | G7: =G6/F6-1 -> 0.050473671 | H7: =H6/G6-1 -> 0.074292288 | I7: =I6/H6-1 -> 0.34028285 | J7: =J6/I6-1 -> 0.18512278 | K7: =K6/J6-1 -> 0.029173127 | ... M7: =M6/L6-1 -> 0.023303806
B9: COGS | C9: =IFERROR(SUM('Data Sheet'!B18,'Data Sheet'!B20:B22)-1*'Data Sheet'!B19,0) -> 9413.84 | D9: =IFERROR(SUM('Data Sheet'!C18,'Data Sheet'!C20:C22)-1*'Data Sheet'!C19,0) -> 9732.66 | E9: =IFERROR(SUM('Data Sheet'!D18,'Data Sheet'!D20:D22)-1*'Data Sheet'!D19,0) -> 11194.17 | F9: =IFERROR(SUM('Data Sheet'!E18,'Data Sheet'!E20:E22)-1*'Data Sheet'!E19,0) -> 12905.81 | G9: =IFERROR(SUM('Data Sheet'!F18,'Data Sheet'!F20:F22)-1*'Data Sheet'!F19,0) -> 13175.16 | H9: =IFERROR(SUM('Data Sheet'!G18,'Data Sheet'!G20:G22)-1*'Data Sheet'!G19,0) -> 14035.07 | I9: =IFERROR(SUM('Data Sheet'!H18,'Data Sheet'!H20:H22)-1*'Data Sheet'!H19,0) -> 20590.57 | J9: =IFERROR(SUM('Data Sheet'!I18,'Data Sheet'!I20:I22)-1*'Data Sheet'!I19,0) -> 23766.7 | ... L9: =IFERROR(SUM('Data Sheet'!K18,'Data Sheet'!K20:K22)-1*'Data Sheet'!K19,0) -> 22741.27 | M9: =IFERROR(SUM('Data Sheet'!H43:K43),0) -> 28350.24
B10: COGS % Sales | C10: =C9/C6 -> 0.65962559 | D10: =D9/D6 -> 0.64617358 | E10: =E9/E6 -> 0.66534736 | F10: =F9/F6 -> 0.67077561 | G10: =G9/G6 -> 0.6518726 | H10: =H9/H6 -> 0.64639643 | I10: =I9/I6 -> 0.7075486 | J10: =J9/J6 -> 0.68911776 | ... M10: =M9/M6 -> 0.81710988
B12: Gross Profit | C12: =C6-C9 -> 4857.65 | D12: =D6-D9 -> 5329.33 | E12: =E6-E9 -> 5630.38 | F12: =F6-F9 -> 6334.32 | G12: =G6-G9 -> 7036.09 | H12: =H6-H9 -> 7677.72 | I12: =I6-I9 -> 8510.71 | J12: =J6-J9 -> 10721.89 | ... M12: =M6-M9 -> 6345.51
B13: Gross Margin | C13: =C12/C6 -> 0.34037441 | D13: =D12/D6 -> 0.35382642 | E13: =E12/E6 -> 0.33465264 | F13: =F12/F6 -> 0.32922439 | G13: =G12/G6 -> 0.3481274 | H13: =H12/H6 -> 0.35360357 | I13: =I12/I6 -> 0.2924514 | J13: =J12/J6 -> 0.31088224 | ... M13: =M12/M6 -> 0.18289012
B15: Selling & General Expenses | C15: =IFERROR(SUM('Data Sheet'!B23:B24),0) -> 2132.61 | D15: =IFERROR(SUM('Data Sheet'!C23:C24),0) -> 2335.57 | E15: =IFERROR(SUM('Data Sheet'!D23:D24),0) -> 2426.37 | F15: =IFERROR(SUM('Data Sheet'!E23:E24),0) -> 2569.38 | G15: =IFERROR(SUM('Data Sheet'!F23:F24),0) -> 2868.7 | H15: =IFERROR(SUM('Data Sheet'!G23:G24),0) -> 2822.12 | I15: =IFERROR(SUM('Data Sheet'!H23:H24),0) -> 3707.1 | J15: =IFERROR(SUM('Data Sheet'!I23:I24),0) -> 4462.05 | ... M15: =IFERROR(SUM('Data Sheet'!L23:L24),0) -> 0
B16: S&G % Sales | C16: =C15/C6 -> 0.14943149 | D16: =D15/D6 -> 0.15506384 | E16: =E15/E6 -> 0.14421604 | F16: =F15/F6 -> 0.13354276 | G16: =G15/G6 -> 0.1419358 | H16: =H15/H6 -> 0.12997501 | I16: =I15/I6 -> 0.12738615 | J16: =J15/J6 -> 0.12937757 | ... M16: =M15/M6 -> 0
B18: EBITDA | C18: =C12-C15 -> 2725.04 | D18: =D12-D15 -> 2993.76 | E18: =E12-E15 -> 3204.01 | F18: =F12-F15 -> 3764.94 | G18: =G12-G15 -> 4167.39 | H18: =H12-H15 -> 4855.6 | I18: =I12-I15 -> 4803.61 | J18: =J12-J15 -> 6259.84 | ... L18: =L12-L15 -> 6006.21 | M18: =IFERROR(SUM('Data Sheet'!H50:K50,'Data Sheet'!H45:K45,'Data Sheet'!H46:K46,'Data Sheet'!K46),0) -> 7802.52
B19: EBIDTA Margin | C19: =C18/C6 -> 0.19094292 | D19: =D18/D6 -> 0.19876258 | E19: =E18/E6 -> 0.19043659 | F19: =F18/F6 -> 0.19568163 | G19: =G18/G6 -> 0.2061916 | H19: =H18/H6 -> 0.22362856 | I19: =I18/I6 -> 0.16506525 | J19: =J18/J6 -> 0.18150467 | ... M19: =M18/M6 -> 0.22488403
B21: Interest | C21: =IFERROR('Data Sheet'!B27,0) -> 49 | D21: =IFERROR('Data Sheet'!C27,0) -> 37.33 | E21: =IFERROR('Data Sheet'!D27,0) -> 41.47 | F21: =IFERROR('Data Sheet'!E27,0) -> 110.47 | G21: =IFERROR('Data Sheet'!F27,0) -> 107.95 | H21: =IFERROR('Data Sheet'!G27,0) -> 91.63 | I21: =IFERROR('Data Sheet'!H27,0) -> 95.41 | J21: =IFERROR('Data Sheet'!I27,0) -> 144.45 | ... L21: =IFERROR('Data Sheet'!K27,0) -> 227.02 | M21: =IFERROR(SUM('Data Sheet'!H46:K46),0) -> 189.1
B22: Interest % Sales | C22: =C21/C6 -> 0.0034334187 | D22: =D21/D6 -> 0.0024784242 | E22: =E21/E6 -> 0.0024648505 | F22: =F21/F6 -> 0.0057416452 | G22: =G21/G6 -> 0.0053410848 | H22: =H21/H6 -> 0.0042200933 | I22: =I21/I6 -> 0.0032785499 | J22: =J21/J6 -> 0.0041883417 | ... M22: =M21/M6 -> 0.0054502353
B24: Depreciation | C24: =IFERROR('Data Sheet'!B26,0) -> 275.58 | D24: =IFERROR('Data Sheet'!C26,0) -> 334.79 | E24: =IFERROR('Data Sheet'!D26,0) -> 360.47 | F24: =IFERROR('Data Sheet'!E26,0) -> 622.14 | G24: =IFERROR('Data Sheet'!F26,0) -> 780.5 | H24: =IFERROR('Data Sheet'!G26,0) -> 791.27 | I24: =IFERROR('Data Sheet'!H26,0) -> 816.36 | J24: =IFERROR('Data Sheet'!I26,0) -> 858.02 | ... L24: =IFERROR('Data Sheet'!K26,0) -> 1026.34 | M24: =IFERROR(SUM('Data Sheet'!H45),0) -> 301.1
B25: Depreciation % Sales | C25: =C24/C6 -> 0.019309827 | D25: =D24/D6 -> 0.022227475 | E25: =E24/E6 -> 0.021425239 | F25: =F24/F6 -> 0.03233554 | G25: =G24/G6 -> 0.038617107 | H25: =H24/H6 -> 0.036442576 | I25: =I24/I6 -> 0.028052374 | J25: =J24/J6 -> 0.024878373 | ... M25: =M24/M6 -> 0.0086782963
B27: Earning Before Tax | C27: =C18-SUM(C21,C24) -> 2400.46 | D27: =D18-SUM(D21,D24) -> 2621.64 | E27: =E18-SUM(E21,E24) -> 2802.07 | F27: =F18-SUM(F21,F24) -> 3032.33 | G27: =G18-SUM(G21,G24) -> 3278.94 | H27: =H18-SUM(H21,H24) -> 3972.7 | I27: =I18-SUM(I21,I24) -> 3891.84 | J27: =J18-SUM(J21,J24) -> 5257.37 | ... M27: =M18-SUM(M21,M24) -> 7312.32
B28: EBT % Sales | C28: =C27/C6 -> 0.16819968 | D28: =D27/D6 -> 0.17405668 | E28: =E27/E6 -> 0.1665465 | F28: =F27/F6 -> 0.15760444 | G28: =G27/G6 -> 0.16223341 | H28: =H27/H6 -> 0.18296589 | I28: =I27/I6 -> 0.13373432 | J28: =J27/J6 -> 0.15243795 | ... M28: =M27/M6 -> 0.2107555
B30: Tax | C30: =IFERROR('Data Sheet'!B29,0) -> 844.49 | D30: =IFERROR('Data Sheet'!C29,0) -> 943.29 | E30: =IFERROR('Data Sheet'!D29,0) -> 1040.96 | F30: =IFERROR('Data Sheet'!E29,0) -> 1098.06 | G30: =IFERROR('Data Sheet'!F29,0) -> 854.85 | H30: =IFERROR('Data Sheet'!G29,0) -> 1097.6 | I30: =IFERROR('Data Sheet'!H29,0) -> 1102.91 | J30: =IFERROR('Data Sheet'!I29,0) -> 1493.5 | ... L30: =IFERROR('Data Sheet'!K29,0) -> 1393.36 | M30: =IFERROR(SUM('Data Sheet'!H48:K48),0) -> 1501.54
B31: Effective Tax Rate | C31: =C30/C27 -> 0.3518034 | D31: =D30/D27 -> 0.35980913 | E31: =E30/E27 -> 0.37149679 | F31: =F30/F27 -> 0.36211758 | G31: =G30/G27 -> 0.26070925 | H31: =H30/H27 -> 0.27628565 | I31: =I30/I27 -> 0.28339038 | J31: =J30/J27 -> 0.2840774 | ... M31: =M30/M27 -> 0.20534386
B33: Net Profit | C33: =IFERROR(C27-C30,0) -> 1555.97 | D33: =IFERROR(D27-D30,0) -> 1678.35 | E33: =IFERROR(E27-E30,0) -> 1761.11 | F33: =IFERROR(F27-F30,0) -> 1934.27 | G33: =IFERROR(G27-G30,0) -> 2424.09 | H33: =IFERROR(H27-H30,0) -> 2875.1 | I33: =IFERROR(I27-I30,0) -> 2788.93 | J33: =IFERROR(J27-J30,0) -> 3763.87 | ... M33: =IFERROR(M27-M30,0) -> 5810.78
B34: Net Profit Margin | C34: =C33/C6 -> 0.10902646 | D34: =D33/D6 -> 0.1114295 | E34: =E33/E6 -> 0.10467501 | F34: =F33/F6 -> 0.1005331 | G34: =G33/G6 -> 0.11993766 | H34: =H33/H6 -> 0.13241504 | I34: =I33/I6 -> 0.095835303 | J34: =J33/J6 -> 0.10913377 | ... M34: =M33/M6 -> 0.16747815
B36: No. of Equity Shares | C36: =IFERROR('Data Sheet'!B93,0) -> 95.92 | D36: =IFERROR('Data Sheet'!C93,0) -> 95.92 | E36: =IFERROR('Data Sheet'!D93,0) -> 95.92 | F36: =IFERROR('Data Sheet'!E93,0) -> 95.92 | G36: =IFERROR('Data Sheet'!F93,0) -> 95.92 | H36: =IFERROR('Data Sheet'!G93,0) -> 95.92 | I36: =IFERROR('Data Sheet'!H93,0) -> 95.92 | J36: =IFERROR('Data Sheet'!I93,0) -> 95.92 | ... M36: =IFERROR('Data Sheet'!L93,0) -> 0
B38: Earning per Shares | C38: =IFERROR(C33/C36,0) -> 16.221539 | D38: =IFERROR(D33/D36,0) -> 17.497394 | E38: =IFERROR(E33/E36,0) -> 18.360196 | F38: =IFERROR(F33/F36,0) -> 20.16545 | G38: =IFERROR(G33/G36,0) -> 25.271997 | H38: =IFERROR(H33/H36,0) -> 29.973937 | I38: =IFERROR(I33/I36,0) -> 29.075584 | J38: =IFERROR(J33/J36,0) -> 39.239679 | ... M38: =IFERROR(M33/M36,0) -> 0
B39: EPS Growth % | D39: =IFERROR(D38/C38-1,0) -> 0.078651902 | E39: =IFERROR(E38/D38-1,0) -> 0.049310335 | F39: =IFERROR(F38/E38-1,0) -> 0.098324352 | G39: =IFERROR(G38/F38-1,0) -> 0.25323249 | H39: =IFERROR(H38/G38-1,0) -> 0.18605332 | I39: =IFERROR(I38/H38-1,0) -> -0.029971131 | J39: =IFERROR(J38/I38-1,0) -> 0.34957493 | K39: =IFERROR(K38/J38-1,0) -> 0.25847333 | ... M39: =IFERROR(M38/L38-1,0) -> -1
B41: Dividend per Share | C41: =IFERROR('Data Sheet'!B31/'Historical FS '!C36,0) -> 7.5 | D41: =IFERROR('Data Sheet'!C31/'Historical FS '!D36,0) -> 10.300042 | E41: =IFERROR('Data Sheet'!D31/'Historical FS '!E36,0) -> 8.6999583 | F41: =IFERROR('Data Sheet'!E31/'Historical FS '!F36,0) -> 10.5 | G41: =IFERROR('Data Sheet'!F31/'Historical FS '!G36,0) -> 12 | H41: =IFERROR('Data Sheet'!G31/'Historical FS '!H36,0) -> 17.849979 | I41: =IFERROR('Data Sheet'!H31/'Historical FS '!I36,0) -> 19.150021 | J41: =IFERROR('Data Sheet'!I31/'Historical FS '!J36,0) -> 25.650021 | ... M41: =IFERROR('Data Sheet'!L31/'Historical FS '!M36,0) -> 0
B42: Dividend pay out Ratio | C42: =IFERROR(C41/C38,0) -> 0.46234825 | D42: =IFERROR(D41/D38,0) -> 0.58866148 | E42: =IFERROR(E41/E38,0) -> 0.47384888 | F42: =IFERROR(F41/F38,0) -> 0.52069256 | G42: =IFERROR(G41/G38,0) -> 0.47483386 | H42: =IFERROR(H41/H38,0) -> 0.59551668 | I42: =IFERROR(I41/I38,0) -> 0.65862894 | J42: =IFERROR(J41/J38,0) -> 0.65367561 | ... M42: =IFERROR(M41/M38,0) -> 0
B44: Retained Earning | C44: =IFERROR(1-C42,0) -> 0.53765175 | D44: =IFERROR(1-D42,0) -> 0.41133852 | E44: =IFERROR(1-E42,0) -> 0.52615112 | F44: =IFERROR(1-F42,0) -> 0.47930744 | G44: =IFERROR(1-G42,0) -> 0.52516614 | H44: =IFERROR(1-H42,0) -> 0.40448332 | I44: =IFERROR(1-I42,0) -> 0.34137106 | J44: =IFERROR(1-J42,0) -> 0.34632439 | ... M44: =IFERROR(1-M42,0) -> 1
B45: Retained Earning | C45: =IFERROR(IF(C38>C41,1-C42,0),0) -> 0.53765175 | D45: =IFERROR(IF(D38>D41,1-D42,0),0) -> 0.41133852 | E45: =IFERROR(IF(E38>E41,1-E42,0),0) -> 0.52615112 | F45: =IFERROR(IF(F38>F41,1-F42,0),0) -> 0.47930744 | G45: =IFERROR(IF(G38>G41,1-G42,0),0) -> 0.52516614 | H45: =IFERROR(IF(H38>H41,1-H42,0),0) -> 0.40448332 | I45: =IFERROR(IF(I38>I41,1-I42,0),0) -> 0.34137106 | J45: =IFERROR(IF(J38>J41,1-J42,0),0) -> 0.34632439 | ... M45: =IFERROR(IF(M38>M41,1-M42,0),0) -> 0
A47: # | B47: Balance Sheet
B48: Equity Share Capital | C48: =IFERROR('Data Sheet'!B57,0) -> 95.92 | D48: =IFERROR('Data Sheet'!C57,0) -> 95.92 | E48: =IFERROR('Data Sheet'!D57,0) -> 95.92 | F48: =IFERROR('Data Sheet'!E57,0) -> 95.92 | G48: =IFERROR('Data Sheet'!F57,0) -> 95.92 | H48: =IFERROR('Data Sheet'!G57,0) -> 95.92 | I48: =IFERROR('Data Sheet'!H57,0) -> 95.92 | J48: =IFERROR('Data Sheet'!I57,0) -> 95.92 | ... L48: =IFERROR('Data Sheet'!K57,0) -> 95.92
B49: Reserves | C49: =IFERROR('Data Sheet'!B58,0) -> 6428.9 | D49: =IFERROR('Data Sheet'!C58,0) -> 7507.97 | E49: =IFERROR('Data Sheet'!D58,0) -> 8314.31 | F49: =IFERROR('Data Sheet'!E58,0) -> 9374.63 | G49: =IFERROR('Data Sheet'!F58,0) -> 10034.24 | H49: =IFERROR('Data Sheet'!G58,0) -> 12710.37 | I49: =IFERROR('Data Sheet'!H58,0) -> 13715.64 | J49: =IFERROR('Data Sheet'!I58,0) -> 15896.31 | ... L49: =IFERROR('Data Sheet'!K58,0) -> 19303.89
B50: Borrowings | C50: =IFERROR('Data Sheet'!B59,0) -> 323.29 | D50: =IFERROR('Data Sheet'!C59,0) -> 560.34 | E50: =IFERROR('Data Sheet'!D59,0) -> 533.43 | F50: =IFERROR('Data Sheet'!E59,0) -> 1319.6 | G50: =IFERROR('Data Sheet'!F59,0) -> 1118.5 | H50: =IFERROR('Data Sheet'!G59,0) -> 1093.12 | I50: =IFERROR('Data Sheet'!H59,0) -> 1586.88 | J50: =IFERROR('Data Sheet'!I59,0) -> 1932.62 | ... L50: =IFERROR('Data Sheet'!K59,0) -> 2290.29
B51: Other Liabilities | C51: =IFERROR('Data Sheet'!B60,0) -> 3710.92 | D51: =IFERROR('Data Sheet'!C60,0) -> 4240.96 | E51: =IFERROR('Data Sheet'!D60,0) -> 4819.82 | F51: =IFERROR('Data Sheet'!E60,0) -> 5458.69 | G51: =IFERROR('Data Sheet'!F60,0) -> 4889.31 | H51: =IFERROR('Data Sheet'!G60,0) -> 6455.93 | I51: =IFERROR('Data Sheet'!H60,0) -> 7559.99 | J51: =IFERROR('Data Sheet'!I60,0) -> 7854.48 | ... L51: =IFERROR('Data Sheet'!K60,0) -> 8665.15
B52: Total Liabilities | C52: =SUM(C48:C51) -> 10559.03 | D52: =SUM(D48:D51) -> 12405.19 | E52: =SUM(E48:E51) -> 13763.48 | F52: =SUM(F48:F51) -> 16248.84 | G52: =SUM(G48:G51) -> 16137.97 | H52: =SUM(H48:H51) -> 20355.34 | I52: =SUM(I48:I51) -> 22958.43 | J52: =SUM(J48:J51) -> 25779.33 | ... L52: =SUM(L48:L51) -> 30355.25
B54: Fixed Assets Net Block | C54: =IFERROR('Data Sheet'!B62,0) -> 3416.35 | D54: =IFERROR('Data Sheet'!C62,0) -> 3303.74 | E54: =IFERROR('Data Sheet'!D62,0) -> 3732.24 | F54: =IFERROR('Data Sheet'!E62,0) -> 6496.56 | G54: =IFERROR('Data Sheet'!F62,0) -> 6272.31 | H54: =IFERROR('Data Sheet'!G62,0) -> 5858.52 | I54: =IFERROR('Data Sheet'!H62,0) -> 5519.06 | J54: =IFERROR('Data Sheet'!I62,0) -> 5770.46 | ... L54: =IFERROR('Data Sheet'!K62,0) -> 9220.1
B55: Capital Work in Progress | C55: =IFERROR('Data Sheet'!B63,0) -> 106.59 | D55: =IFERROR('Data Sheet'!C63,0) -> 257.54 | E55: =IFERROR('Data Sheet'!D63,0) -> 1405.11 | F55: =IFERROR('Data Sheet'!E63,0) -> 209.67 | G55: =IFERROR('Data Sheet'!F63,0) -> 140.24 | H55: =IFERROR('Data Sheet'!G63,0) -> 182.98 | I55: =IFERROR('Data Sheet'!H63,0) -> 426.43 | J55: =IFERROR('Data Sheet'!I63,0) -> 1019.59 | ... L55: =IFERROR('Data Sheet'!K63,0) -> 1254.49
B56: Investments | C56: =IFERROR('Data Sheet'!B64,0) -> 2712.13 | D56: =IFERROR('Data Sheet'!C64,0) -> 2651.99 | E56: =IFERROR('Data Sheet'!D64,0) -> 2140.7 | F56: =IFERROR('Data Sheet'!E64,0) -> 2568.58 | G56: =IFERROR('Data Sheet'!F64,0) -> 2018.85 | H56: =IFERROR('Data Sheet'!G64,0) -> 4736.8 | I56: =IFERROR('Data Sheet'!H64,0) -> 3247.53 | J56: =IFERROR('Data Sheet'!I64,0) -> 4261.71 | ... L56: =IFERROR('Data Sheet'!K64,0) -> 4724.75
B57: Other Assets | C57: =IFERROR('Data Sheet'!B65-SUM('Data Sheet'!B67:B69),0) -> 714.72 | D57: =IFERROR('Data Sheet'!C65-SUM('Data Sheet'!C67:C69),0) -> 1317.17 | E57: =IFERROR('Data Sheet'!D65-SUM('Data Sheet'!D67:D69),0) -> 1691.84 | F57: =IFERROR('Data Sheet'!E65-SUM('Data Sheet'!E67:E69),0) -> 1471.96 | G57: =IFERROR('Data Sheet'!F65-SUM('Data Sheet'!F67:F69),0) -> 1738.71 | H57: =IFERROR('Data Sheet'!G65-SUM('Data Sheet'!G67:G69),0) -> 2565.52 | I57: =IFERROR('Data Sheet'!H65-SUM('Data Sheet'!H67:H69),0) -> 2876.66 | J57: =IFERROR('Data Sheet'!I65-SUM('Data Sheet'!I67:I69),0) -> 3036.17 | ... L57: =IFERROR('Data Sheet'!K65-SUM('Data Sheet'!K67:K69),0) -> 3341.01
...

Sheet Ratio Analysis
B2: ="Ratio Analysis - "&'Data Sheet'!B1 -> Ratio Analysis - ASIAN PAINTS LTD
B3: Years | C3: ='Data Sheet'!B16 -> 42460 | D3: ='Data Sheet'!C16 -> 42825 | E3: ='Data Sheet'!D16 -> 43190 | F3: ='Data Sheet'!E16 -> 43555 | G3: ='Data Sheet'!F16 -> 43921 | H3: ='Data Sheet'!G16 -> 44286 | I3: ='Data Sheet'!H16 -> 44651 | J3: ='Data Sheet'!I16 -> 45016 | ... L3: ='Data Sheet'!K16 -> 45747 | M3: Trend | N3: Mean | O3: Medin
O4: Medin
B5: SalesGrowth | D5: =IFERROR('Historical FS '!D7,0) -> 0.055390152 | E5: =IFERROR('Historical FS '!E7,0) -> 0.11702039 | F5: =IFERROR('Historical FS '!F7,0) -> 0.14357472 | G5: =IFERROR('Historical FS '!G7,0) -> 0.050473671 | H5: =IFERROR('Historical FS '!H7,0) -> 0.074292288 | I5: =IFERROR('Historical FS '!I7,0) -> 0.34028285 | J5: =IFERROR('Historical FS '!J7,0) -> 0.18512278 | K5: =IFERROR('Historical FS '!K7,0) -> 0.029173127 | L5: =IFERROR('Historical FS '!L7,0) -> -0.044770308 | N5: =IFERROR(AVERAGE(D5:L5),0) -> 0.10561774 | O5: =IFERROR(MEDIAN(D5:L5),0) -> 0.074292288
B6: Gross Margin | D6: =IFERROR('Historical FS '!C13,0) -> 0.34037441 | E6: =IFERROR('Historical FS '!D13,0) -> 0.35382642 | F6: =IFERROR('Historical FS '!E13,0) -> 0.33465264 | G6: =IFERROR('Historical FS '!F13,0) -> 0.32922439 | H6: =IFERROR('Historical FS '!G13,0) -> 0.3481274 | I6: =IFERROR('Historical FS '!H13,0) -> 0.35360357 | J6: =IFERROR('Historical FS '!I13,0) -> 0.2924514 | K6: =IFERROR('Historical FS '!J13,0) -> 0.31088224 | L6: =IFERROR('Historical FS '!K13,0) -> 0.35173503 | N6: =IFERROR(AVERAGE(D6:L6),0) -> 0.33498639 | O6: =IFERROR(MEDIAN(D6:L6),0) -> 0.34037441
B7: EBITDA Growth | D7: =IFERROR('Historical FS '!D18/'Historical FS '!C18-1,0) -> 0.098611397 | E7: =IFERROR('Historical FS '!E18/'Historical FS '!D18-1,0) -> 0.070229411 | F7: =IFERROR('Historical FS '!F18/'Historical FS '!E18-1,0) -> 0.17507124 | G7: =IFERROR('Historical FS '!G18/'Historical FS '!F18-1,0) -> 0.10689413 | H7: =IFERROR('Historical FS '!H18/'Historical FS '!G18-1,0) -> 0.16514173 | I7: =IFERROR('Historical FS '!I18/'Historical FS '!H18-1,0) -> -0.010707225 | J7: =IFERROR('Historical FS '!J18/'Historical FS '!I18-1,0) -> 0.30315325 | K7: =IFERROR('Historical FS '!K18/'Historical FS '!J18-1,0) -> 0.21168912 | L7: =IFERROR('Historical FS '!L18/'Historical FS '!K18-1,0) -> -0.20814425 | N7: =IFERROR(AVERAGE(D7:L7),0) -> 0.10132653 | O7: =IFERROR(MEDIAN(D7:L7),0) -> 0.10689413
B8: EBIT Growth | D8: =IFERROR(('Historical FS '!D18-'Historical FS '!D24)/('Historical FS '!C18-'Historical FS '!C24)-1,0) -> 0.085533138 | E8: =IFERROR(('Historical FS '!E18-'Historical FS '!E24)/('Historical FS '!D18-'Historical FS '!D24)-1,0) -> 0.069414096 | F8: =IFERROR(('Historical FS '!F18-'Historical FS '!F24)/('Historical FS '!E18-'Historical FS '!E24)-1,0) -> 0.10524206 | G8: =IFERROR(('Historical FS '!G18-'Historical FS '!G24)/('Historical FS '!F18-'Historical FS '!F24)-1,0) -> 0.077666412 | H8: =IFERROR(('Historical FS '!H18-'Historical FS '!H24)/('Historical FS '!G18-'Historical FS '!G24)-1,0) -> 0.20001831 | I8: =IFERROR(('Historical FS '!I18-'Historical FS '!I24)/('Historical FS '!H18-'Historical FS '!H24)-1,0) -> -0.018964995 | J8: =IFERROR(('Historical FS '!J18-'Historical FS '!J24)/('Historical FS '!I18-'Historical FS '!I24)-1,0) -> 0.35477334 | K8: =IFERROR(('Historical FS '!K18-'Historical FS '!K24)/('Historical FS '!J18-'Historical FS '!J24)-1,0) -> 0.24624293 | L8: =IFERROR(('Historical FS '!L18-'Historical FS '!L24)/('Historical FS '!K18-'Historical FS '!K24)-1,0) -> -0.26026667 | N8: =IFERROR(AVERAGE(D8:L8),0) -> 0.095517624 | O8: =IFERROR(MEDIAN(D8:L8),0) -> 0.085533138
B9: EBI Growth | D9: =IFERROR('Historical FS '!D27/'Historical FS '!C27-1,9) -> 0.092140673 | E9: =IFERROR('Historical FS '!E27/'Historical FS '!D27-1,9) -> 0.068823332 | F9: =IFERROR('Historical FS '!F27/'Historical FS '!E27-1,9) -> 0.082174964 | G9: =IFERROR('Historical FS '!G27/'Historical FS '!F27-1,9) -> 0.0813269 | H9: =IFERROR('Historical FS '!H27/'Historical FS '!G27-1,9) -> 0.21158057 | I9: =IFERROR('Historical FS '!I27/'Historical FS '!H27-1,9) -> -0.020353915 | J9: =IFERROR('Historical FS '!J27/'Historical FS '!I27-1,9) -> 0.35087003 | K9: =IFERROR('Historical FS '!K27/'Historical FS '!J27-1,9) -> 0.24145913 | L9: =IFERROR('Historical FS '!L27/'Historical FS '!K27-1,9) -> -0.27179587 | N9: =IFERROR(AVERAGE(D9:L9),0) -> 0.092913979 | O9: =IFERROR(MEDIAN(D9:L9),0) -> 0.082174964
B10: Net Profit Growth | D10: =IFERROR('Historical FS '!D33/'Historical FS '!C33-1,0) -> 0.078651902 | E10: =IFERROR('Historical FS '!E33/'Historical FS '!D33-1,0) -> 0.049310335 | F10: =IFERROR('Historical FS '!F33/'Historical FS '!E33-1,0) -> 0.098324352 | G10: =IFERROR('Historical FS '!G33/'Historical FS '!F33-1,0) -> 0.25323249 | H10: =IFERROR('Historical FS '!H33/'Historical FS '!G33-1,0) -> 0.18605332 | I10: =IFERROR('Historical FS '!I33/'Historical FS '!H33-1,0) -> -0.029971131 | J10: =IFERROR('Historical FS '!J33/'Historical FS '!I33-1,0) -> 0.34957493 | K10: =IFERROR('Historical FS '!K33/'Historical FS '!J33-1,0) -> 0.25847333 | L10: =IFERROR('Historical FS '!L33/'Historical FS '!K33-1,0) -> -0.29075755 | N10: =IFERROR(AVERAGE(D10:L10),0) -> 0.10587689 | O10: =IFERROR(MEDIAN(D10:L10),0) -> 0.098324352
B11: Dividend Growth | D11: =IFERROR('Historical FS '!D41/'Historical FS '!C41-1,) -> 0.37333889 | E11: =IFERROR('Historical FS '!E41/'Historical FS '!D41-1,) -> -0.15534727 | F11: =IFERROR('Historical FS '!F41/'Historical FS '!E41-1,) -> 0.20690234 | G11: =IFERROR('Historical FS '!G41/'Historical FS '!F41-1,) -> 0.14285714 | H11: =IFERROR('Historical FS '!H41/'Historical FS '!G41-1,) -> 0.48749826 | I11: =IFERROR('Historical FS '!I41/'Historical FS '!H41-1,) -> 0.072831553 | J11: =IFERROR('Historical FS '!J41/'Historical FS '!I41-1,) -> 0.33942522 | K11: =IFERROR('Historical FS '!K41/'Historical FS '!J41-1,) -> 0.29824618 | L11: =IFERROR('Historical FS '!L41/'Historical FS '!K41-1,) -> -0.25525494 | N11: =IFERROR(AVERAGE(D11:L11),0) -> 0.16783304 | O11: =IFERROR(MEDIAN(D11:L11),0) -> 0.20690234
B13: Gross Margin | C13: =IFERROR('Historical FS '!C13,0) -> 0.34037441 | D13: =IFERROR('Historical FS '!D13,0) -> 0.35382642 | E13: =IFERROR('Historical FS '!E13,0) -> 0.33465264 | F13: =IFERROR('Historical FS '!F13,0) -> 0.32922439 | G13: =IFERROR('Historical FS '!G13,0) -> 0.3481274 | H13: =IFERROR('Historical FS '!H13,0) -> 0.35360357 | I13: =IFERROR('Historical FS '!I13,0) -> 0.2924514 | J13: =IFERROR('Historical FS '!J13,0) -> 0.31088224 | ... L13: =IFERROR('Historical FS '!L13,0) -> 0.32927727 | N13: =IFERROR(AVERAGE(C13:L13),0) -> 0.33441548 | O13: =IFERROR(MEDIAN(C13:L13),0) -> 0.33751352
B14: EBITDA Margin | C14: =IFERROR('Historical FS '!C19,0) -> 0.19094292 | D14: =IFERROR('Historical FS '!D19,0) -> 0.19876258 | E14: =IFERROR('Historical FS '!E19,0) -> 0.19043659 | F14: =IFERROR('Historical FS '!F19,0) -> 0.19568163 | G14: =IFERROR('Historical FS '!G19,0) -> 0.2061916 | H14: =IFERROR('Historical FS '!H19,0) -> 0.22362856 | I14: =IFERROR('Historical FS '!I19,0) -> 0.16506525 | J14: =IFERROR('Historical FS '!J19,0) -> 0.18150467 | ... L14: =IFERROR('Historical FS '!L19,0) -> 0.17714497 | N14: =IFERROR(AVERAGE(C14:L14),0) -> 0.19430519 | O14: =IFERROR(MEDIAN(C14:L14),0) -> 0.19331228
B15: EBIT Margin | C15: =IFERROR(('Historical FS '!C18-'Historical FS '!C24)/'Historical FS '!C6,0) -> 0.1716331 | D15: =IFERROR(('Historical FS '!D18-'Historical FS '!D24)/'Historical FS '!D6,0) -> 0.17653511 | E15: =IFERROR(('Historical FS '!E18-'Historical FS '!E24)/'Historical FS '!E6,0) -> 0.16901136 | F15: =IFERROR(('Historical FS '!F18-'Historical FS '!F24)/'Historical FS '!F6,0) -> 0.16334609 | G15: =IFERROR(('Historical FS '!G18-'Historical FS '!G24)/'Historical FS '!G6,0) -> 0.16757449 | H15: =IFERROR(('Historical FS '!H18-'Historical FS '!H24)/'Historical FS '!H6,0) -> 0.18718599 | I15: =IFERROR(('Historical FS '!I18-'Historical FS '!I24)/'Historical FS '!I6,0) -> 0.13701287 | J15: =IFERROR(('Historical FS '!J18-'Historical FS '!J24)/'Historical FS '!J6,0) -> 0.15662629 | ... L15: =IFERROR(('Historical FS '!L18-'Historical FS '!L24)/'Historical FS '!L6,0) -> 0.14687447 | N15: =IFERROR(AVERAGE(C15:L15),0) -> 0.16654612 | O15: =IFERROR(MEDIAN(C15:L15),0) -> 0.16829292
B16: EBT Margin | C16: =IFERROR('Historical FS '!C28,0) -> 0.16819968 | D16: =IFERROR('Historical FS '!D28,0) -> 0.17405668 | E16: =IFERROR('Historical FS '!E28,0) -> 0.1665465 | F16: =IFERROR('Historical FS '!F28,0) -> 0.15760444 | G16: =IFERROR('Historical FS '!G28,0) -> 0.16223341 | H16: =IFERROR('Historical FS '!H28,0) -> 0.18296589 | I16: =IFERROR('Historical FS '!I28,0) -> 0.13373432 | J16: =IFERROR('Historical FS '!J28,0) -> 0.15243795 | ... L16: =IFERROR('Historical FS '!L28,0) -> 0.14017883 | N16: =IFERROR(AVERAGE(C16:L16),0) -> 0.16218388 | O16: =IFERROR(MEDIAN(C16:L16),0) -> 0.16438996
B17: Net Profit Margin | C17: =IFERROR('Historical FS '!C34,0) -> 0.10902646 | D17: =IFERROR('Historical FS '!D34,0) -> 0.1114295 | E17: =IFERROR('Historical FS '!E34,0) -> 0.10467501 | F17: =IFERROR('Historical FS '!F34,0) -> 0.1005331 | G17: =IFERROR('Historical FS '!G34,0) -> 0.11993766 | H17: =IFERROR('Historical FS '!H34,0) -> 0.13241504 | I17: =IFERROR('Historical FS '!I34,0) -> 0.095835303 | J17: =IFERROR('Historical FS '!J34,0) -> 0.10913377 | ... L17: =IFERROR('Historical FS '!L34,0) -> 0.099083574 | N17: =IFERROR(AVERAGE(C17:L17),0) -> 0.11155183 | O17: =IFERROR(MEDIAN(C17:L17),0) -> 0.10908012
B19: Sales Expense % Sales | C19: =IFERROR('Historical FS '!C16,0) -> 0.14943149 | D19: =IFERROR('Historical FS '!D16,0) -> 0.15506384 | E19: =IFERROR('Historical FS '!E16,0) -> 0.14421604 | F19: =IFERROR('Historical FS '!F16,0) -> 0.13354276 | G19: =IFERROR('Historical FS '!G16,0) -> 0.1419358 | H19: =IFERROR('Historical FS '!H16,0) -> 0.12997501 | I19: =IFERROR('Historical FS '!I16,0) -> 0.12738615 | J19: =IFERROR('Historical FS '!J16,0) -> 0.12937757 | ... L19: =IFERROR('Historical FS '!L16,0) -> 0.1521323 | N19: =IFERROR(AVERAGE(C19:L19),0) -> 0.14011029 | O19: =IFERROR(MEDIAN(C19:L19),0) -> 0.13998885
B20: Depreciation % Sales | C20: =IFERROR('Historical FS '!C25,0) -> 0.019309827 | D20: =IFERROR('Historical FS '!D25,0) -> 0.022227475 | E20: =IFERROR('Historical FS '!E25,0) -> 0.021425239 | F20: =IFERROR('Historical FS '!F25,0) -> 0.03233554 | G20: =IFERROR('Historical FS '!G25,0) -> 0.038617107 | H20: =IFERROR('Historical FS '!H25,0) -> 0.036442576 | I20: =IFERROR('Historical FS '!I25,0) -> 0.028052374 | J20: =IFERROR('Historical FS '!J25,0) -> 0.024878373 | ... L20: =IFERROR('Historical FS '!L25,0) -> 0.030270498 | N20: =IFERROR(AVERAGE(C20:L20),0) -> 0.027759074 | O20: =IFERROR(MEDIAN(C20:L20),0) -> 0.026465374
B21: Operating Income % Sales | C21: =C15 -> 0.1716331 | D21: =D15 -> 0.17653511 | E21: =E15 -> 0.16901136 | F21: =F15 -> 0.16334609 | G21: =G15 -> 0.16757449 | H21: =H15 -> 0.18718599 | I21: =I15 -> 0.13701287 | J21: =J15 -> 0.15662629 | ... L21: =L15 -> 0.14687447 | N21: =IFERROR(AVERAGE(C21:L21),0) -> 0.16654612 | O21: =IFERROR(MEDIAN(C21:L21),0) -> 0.16829292
B23: Return On Capital Employed | C23: =IFERROR(('Historical FS '!C18-'Historical FS '!C24)/SUM('Historical FS '!C48:C50),0) -> 0.35768409 | D23: =IFERROR(('Historical FS '!D18-'Historical FS '!D24)/SUM('Historical FS '!D48:D50),0) -> 0.32568534 | E23: =IFERROR(('Historical FS '!E18-'Historical FS '!E24)/SUM('Historical FS '!E48:E50),0) -> 0.31793919 | F23: =IFERROR(('Historical FS '!F18-'Historical FS '!F24)/SUM('Historical FS '!F48:F50),0) -> 0.29126565 | G23: =IFERROR(('Historical FS '!G18-'Historical FS '!G24)/SUM('Historical FS '!G48:G50),0) -> 0.30109275 | H23: =IFERROR(('Historical FS '!H18-'Historical FS '!H24)/SUM('Historical FS '!H48:H50),0) -> 0.29241025 | I23: =IFERROR(('Historical FS '!I18-'Historical FS '!I24)/SUM('Historical FS '!I48:I50),0) -> 0.25893857 | J23: =IFERROR(('Historical FS '!J18-'Historical FS '!J24)/SUM('Historical FS '!J48:J50),0) -> 0.30135929 | ... L23: =IFERROR(('Historical FS '!L18-'Historical FS '!L24)/SUM('Historical FS '!L48:L50),0) -> 0.22959184 | N23: =IFERROR(AVERAGE(C23:L23),0) -> 0.29934731 | O23: =IFERROR(MEDIAN(C23:L23),0) -> 0.30122602
B24: Retained Earning % | C24: =IFERROR('Historical FS '!C44,0) -> 0.53765175 | D24: =IFERROR('Historical FS '!D44,0) -> 0.41133852 | E24: =IFERROR('Historical FS '!E44,0) -> 0.52615112 | F24: =IFERROR('Historical FS '!F44,0) -> 0.47930744 | G24: =IFERROR('Historical FS '!G44,0) -> 0.52516614 | H24: =IFERROR('Historical FS '!H44,0) -> 0.40448332 | I24: =IFERROR('Historical FS '!I44,0) -> 0.34137106 | J24: =IFERROR('Historical FS '!J44,0) -> 0.34632439 | ... L24: =IFERROR('Historical FS '!L44,0) -> 0.29191038 | N24: =IFERROR(AVERAGE(C24:L24),0) -> 0.41893697 | O24: =IFERROR(MEDIAN(C24:L24),0) -> 0.40791092
B25: Return On Equity | C25: =IFERROR('Historical FS '!C33/SUM('Historical FS '!C48:C49),0) -> 0.23846941 | D25: =IFERROR('Historical FS '!D33/SUM('Historical FS '!D48:D49),0) -> 0.22072255 | E25: =IFERROR('Historical FS '!E33/SUM('Historical FS '!E48:E49),0) -> 0.20940093 | F25: =IFERROR('Historical FS '!F33/SUM('Historical FS '!F48:F49),0) -> 0.20424051 | G25: =IFERROR('Historical FS '!G33/SUM('Historical FS '!G48:G49),0) -> 0.23929434 | H25: =IFERROR('Historical FS '!H33/SUM('Historical FS '!H48:H49),0) -> 0.22450686 | I25: =IFERROR('Historical FS '!I33/SUM('Historical FS '!I48:I49),0) -> 0.20192723 | J25: =IFERROR('Historical FS '!J33/SUM('Historical FS '!J48:J49),0) -> 0.23535617 | ... L25: =IFERROR('Historical FS '!L33/SUM('Historical FS '!L48:L49),0) -> 0.17317128 | N25: =IFERROR(AVERAGE(C25:L25),0) -> 0.22000076 | O25: =IFERROR(MEDIAN(C25:L25),0) -> 0.22261471
B26: Self Sustained Growth Rate | C26: =C24*C25 -> 0.1282135 | D26: =D24*D25 -> 0.090791687 | E26: =E24*E25 -> 0.11017654 | F26: =F24*F25 -> 0.097893998 | G26: =G24*G25 -> 0.12566929 | H26: =H24*H25 -> 0.090809282 | I26: =I24*I25 -> 0.068932112 | J26: =J24*J25 -> 0.081509583 | ... L26: =L24*L25 -> 0.050550495 | N26: =IFERROR(AVERAGE(C26:L26),0) -> 0.092691327 | O26: =IFERROR(MEDIAN(C26:L26),0) -> 0.090800484
B27: Interest Coverage Ratio | C27: =('Historical FS '!C18-'Historical FS '!C24)/'Historical FS '!C21 -> 49.98898 | D27: =('Historical FS '!D18-'Historical FS '!D24)/'Historical FS '!D21 -> 71.22877 | E27: =('Historical FS '!E18-'Historical FS '!E24)/'Historical FS '!E21 -> 68.568604 | F27: =('Historical FS '!F18-'Historical FS '!F24)/'Historical FS '!F21 -> 28.449353 | G27: =('Historical FS '!G18-'Historical FS '!G24)/'Historical FS '!G21 -> 31.374618 | H27: =('Historical FS '!H18-'Historical FS '!H24)/'Historical FS '!H21 -> 44.355888 | I27: =('Historical FS '!I18-'Historical FS '!I24)/'Historical FS '!I21 -> 41.790693 | J27: =('Historical FS '!J18-'Historical FS '!J24)/'Historical FS '!J21 -> 37.395777 | ... L27: =('Historical FS '!L18-'Historical FS '!L24)/'Historical FS '!L21 -> 21.935821 | N27: =IFERROR(AVERAGE(C27:L27),0) -> 42.790022 | O27: =IFERROR(MEDIAN(C27:L27),0) -> 39.593235
B29: Debtor Turnover Ratio | C29: =IFERROR('Historical FS '!C6/'Historical FS '!C60,0) -> 12.02478 | D29: =IFERROR('Historical FS '!D6/'Historical FS '!D60,0) -> 10.411994 | E29: =IFERROR('Historical FS '!E6/'Historical FS '!E60,0) -> 9.7216332 | F29: =IFERROR('Historical FS '!F6/'Historical FS '!F60,0) -> 10.087468 | G29: =IFERROR('Historical FS '!G6/'Historical FS '!G60,0) -> 11.258369 | H29: =IFERROR('Historical FS '!H6/'Historical FS '!H60,0) -> 8.344109 | I29: =IFERROR('Historical FS '!I6/'Historical FS '!I60,0) -> 7.5169136 | J29: =IFERROR('Historical FS '!J6/'Historical FS '!J60,0) -> 7.4377909 | ... L29: =IFERROR('Historical FS '!L6/'Historical FS '!L60,0) -> 7.8600767 | N29: =IFERROR(AVERAGE(C29:L29),0) -> 9.1923181 | O29: =IFERROR(MEDIAN(C29:L29),0) -> 9.0328711
B30: Creditor Turnover Ratio | C30: =IFERROR('Historical FS '!C6/'Historical FS '!C51,0) -> 3.8458091 | D30: =IFERROR('Historical FS '!D6/'Historical FS '!D51,0) -> 3.551552 | E30: =IFERROR('Historical FS '!E6/'Historical FS '!E51,0) -> 3.4907009 | F30: =IFERROR('Historical FS '!F6/'Historical FS '!F51,0) -> 3.524679 | G30: =IFERROR('Historical FS '!G6/'Historical FS '!G51,0) -> 4.1337633 | H30: =IFERROR('Historical FS '!H6/'Historical FS '!H51,0) -> 3.3632319 | I30: =IFERROR('Historical FS '!I6/'Historical FS '!I51,0) -> 3.8493808 | J30: =IFERROR('Historical FS '!J6/'Historical FS '!J51,0) -> 4.390945 | ... L30: =IFERROR('Historical FS '!L6/'Historical FS '!L51,0) -> 3.9128717 | N30: =IFERROR(AVERAGE(C30:L30),0) -> 3.8143684 | O30: =IFERROR(MEDIAN(C30:L30),0) -> 3.8475949
B31: Inventory Turnover | C31: =IFERROR('Historical FS '!C6/'Historical FS '!C61,0) -> 7.14203 | D31: =IFERROR('Historical FS '!D6/'Historical FS '!D61,0) -> 5.7336635 | E31: =IFERROR('Historical FS '!E6/'Historical FS '!E61,0) -> 6.3290399 | F31: =IFERROR('Historical FS '!F6/'Historical FS '!F61,0) -> 6.1082493 | G31: =IFERROR('Historical FS '!G6/'Historical FS '!G61,0) -> 5.9623548 | H31: =IFERROR('Historical FS '!H6/'Historical FS '!H61,0) -> 5.715998 | I31: =IFERROR('Historical FS '!I6/'Historical FS '!I61,0) -> 4.7296237 | J31: =IFERROR('Historical FS '!J6/'Historical FS '!J61,0) -> 5.5531459 | ... L31: =IFERROR('Historical FS '!L6/'Historical FS '!L61,0) -> 5.0460273 | N31: =IFERROR(AVERAGE(C31:L31),0) -> 5.8312412 | O31: =IFERROR(MEDIAN(C31:L31),0) -> 5.8480092
B32: Fixed Asset Turnover | C32: =IFERROR('Historical FS '!C6/'Historical FS '!C54,0) -> 4.1774086 | D32: =IFERROR('Historical FS '!D6/'Historical FS '!D54,0) -> 4.5590724 | E32: =IFERROR('Historical FS '!E6/'Historical FS '!E54,0) -> 4.5078961 | F32: =IFERROR('Historical FS '!F6/'Historical FS '!F54,0) -> 2.9615874 | G32: =IFERROR('Historical FS '!G6/'Historical FS '!G54,0) -> 3.2222977 | H32: =IFERROR('Historical FS '!H6/'Historical FS '!H54,0) -> 3.7061903 | I32: =IFERROR('Historical FS '!I6/'Historical FS '!I54,0) -> 5.2728689 | J32: =IFERROR('Historical FS '!J6/'Historical FS '!J54,0) -> 5.9767488 | ... L32: =IFERROR('Historical FS '!L6/'Historical FS '!L54,0) -> 3.6773592 | N32: =IFERROR(AVERAGE(C32:L32),0) -> 4.3028075 | O32: =IFERROR(MEDIAN(C32:L32),0) -> 4.3426524
B33: Capital Turnover Ratio | C33: =IFERROR('Historical FS '!C6/SUM('Historical FS '!C48:C49),0) -> 2.1872619 | D33: =IFERROR('Historical FS '!D6/SUM('Historical FS '!D48:D49),0) -> 1.9808269 | E33: =IFERROR('Historical FS '!E6/SUM('Historical FS '!E48:E49),0) -> 2.0004863 | F33: =IFERROR('Historical FS '!F6/SUM('Historical FS '!F48:F49),0) -> 2.0315747 | G33: =IFERROR('Historical FS '!G6/SUM('Historical FS '!G48:G49),0) -> 1.995156 | H33: =IFERROR('Historical FS '!H6/SUM('Historical FS '!H48:H49),0) -> 1.6954785 | I33: =IFERROR('Historical FS '!I6/SUM('Historical FS '!I48:I49),0) -> 2.1070234 | J33: =IFERROR('Historical FS '!J6/SUM('Historical FS '!J48:J49),0) -> 2.1565842 | ... L33: =IFERROR('Historical FS '!L6/SUM('Historical FS '!L48:L49),0) -> 1.7477295 | N33: =IFERROR(AVERAGE(C33:L33),0) -> 1.9797367 | O33: =IFERROR(MEDIAN(C33:L33),0) -> 1.9978212
B35: Debtors Days | C35: =IFERROR(365/C29,0) -> 30.353985 | D35: =IFERROR(365/D29,0) -> 35.055726 | E35: =IFERROR(365/E29,0) -> 37.545132 | F35: =IFERROR(365/F29,0) -> 36.183511 | G35: =IFERROR(365/G29,0) -> 32.420325 | H35: =IFERROR(365/H29,0) -> 43.743436 | I35: =IFERROR(365/I29,0) -> 48.557163 | J35: =IFERROR(365/J29,0) -> 49.073711 | ... L35: =IFERROR(365/L29,0) -> 46.437206 | N35: =IFERROR(AVERAGE(C35:L35),0) -> 40.964536 | O35: =IFERROR(MEDIAN(C35:L35),0) -> 40.644284
B36: Payable Days | C36: =IFERROR(365/C30,0) -> 94.908506 | D36: =IFERROR(365/D30,0) -> 102.77197 | E36: =IFERROR(365/E30,0) -> 104.56353 | F36: =IFERROR(365/F30,0) -> 103.55553 | G36: =IFERROR(365/G30,0) -> 88.297268 | H36: =IFERROR(365/H30,0) -> 108.52656 | I36: =IFERROR(365/I30,0) -> 94.820446 | J36: =IFERROR(365/J30,0) -> 83.125613 | ... L36: =IFERROR(365/L30,0) -> 93.281873 | N36: =IFERROR(AVERAGE(C36:L36),0) -> 96.329564 | O36: =IFERROR(MEDIAN(C36:L36),0) -> 94.864476
B37: Inventory Days | C37: =IFERROR(365/C31,0) -> 51.105918 | D37: =IFERROR(365/D31,0) -> 63.659125 | E37: =IFERROR(365/E31,0) -> 57.670675 | F37: =IFERROR(365/F31,0) -> 59.755256 | G37: =IFERROR(365/G31,0) -> 61.217423 | H37: =IFERROR(365/H31,0) -> 63.855866 | I37: =IFERROR(365/I31,0) -> 77.173159 | J37: =IFERROR(365/J31,0) -> 65.728509 | ... L37: =IFERROR(365/L31,0) -> 72.334131 | N37: =IFERROR(AVERAGE(C37:L37),0) -> 63.341177 | O37: =IFERROR(MEDIAN(C37:L37),0) -> 62.438274
B38: Cash Conversion Cycle (In days) | C38: =SUM(C35,C37)-C36 -> -13.448603 | D38: =SUM(D35,D37)-D36 -> -4.0571199 | E38: =SUM(E35,E37)-E36 -> -9.347721 | F38: =SUM(F35,F37)-F36 -> -7.6167625 | G38: =SUM(G35,G37)-G36 -> 5.3404812 | H38: =SUM(H35,H37)-H36 -> -0.92725992 | I38: =SUM(I35,I37)-I36 -> 30.909876 | J38: =SUM(J35,J37)-J36 -> 31.676607 | ... L38: =SUM(L35,L37)-L36 -> 25.489463 | N38: =IFERROR(AVERAGE(C38:L38),0) -> 7.9761485 | O38: =IFERROR(MEDIAN(C38:L38),0) -> 2.2066106
B40: CFO/Sales | C40: =IFERROR('Historical FS '!C107/'Historical FS '!C6,0) -> 0.17111037 | D40: =IFERROR('Historical FS '!D107/'Historical FS '!D6,0) -> 0.061412868 | E40: =IFERROR('Historical FS '!E107/'Historical FS '!E6,0) -> 0.12083533 | F40: =IFERROR('Historical FS '!F107/'Historical FS '!F6,0) -> 0.10701591 | G40: =IFERROR('Historical FS '!G107/'Historical FS '!G6,0) -> 0.093710186 | H40: =IFERROR('Historical FS '!H107/'Historical FS '!H6,0) -> 0.16013603 | I40: =IFERROR('Historical FS '!I107/'Historical FS '!I6,0) -> -0.062127851 | J40: =IFERROR('Historical FS '!J107/'Historical FS '!J6,0) -> 0.099221221 | ... L40: =IFERROR('Historical FS '!L107/'Historical FS '!L6,0) -> 0.11369797 | N40: =IFERROR(AVERAGE(C40:L40),0) -> 0.1037263 | O40: =IFERROR(MEDIAN(C40:L40),0) -> 0.11035694
B41: CFO/total Assets | C41: =IFERROR('Historical FS '!C107/'Historical FS '!C65,0) -> 0.23127037 | D41: =IFERROR('Historical FS '!D107/'Historical FS '!D65,0) -> 0.074565565 | E41: =IFERROR('Historical FS '!E107/'Historical FS '!E65,0) -> 0.14770974 | F41: =IFERROR('Historical FS '!F107/'Historical FS '!F65,0) -> 0.12671674 | G41: =IFERROR('Historical FS '!G107/'Historical FS '!G65,0) -> 0.11736296 | H41: =IFERROR('Historical FS '!H107/'Historical FS '!H65,0) -> 0.17081513 | I41: =IFERROR('Historical FS '!I107/'Historical FS '!I65,0) -> -0.07875103 | J41: =IFERROR('Historical FS '!J107/'Historical FS '!J65,0) -> 0.13274201 | ... L41: =IFERROR('Historical FS '!L107/'Historical FS '!L65,0) -> 0.12699615 | N41: =IFERROR(AVERAGE(C41:L41),0) -> 0.1253904 | O41: =IFERROR(MEDIAN(C41:L41),0) -> 0.12986908
B42: CFO/Total Debt | C42: =IFERROR('Historical FS '!C107/'Historical FS '!C50,0) -> 7.5535897 | D42: =IFERROR('Historical FS '!D107/'Historical FS '!D50,0) -> 1.6507835 | E42: =IFERROR('Historical FS '!E107/'Historical FS '!E50,0) -> 3.8111842 | F42: =IFERROR('Historical FS '!F107/'Historical FS '!F50,0) -> 1.5603213 | G42: =IFERROR('Historical FS '!G107/'Historical FS '!G50,0) -> 1.6933393 | H42: =IFERROR('Historical FS '!H107/'Historical FS '!H50,0) -> 3.1808036 | I42: =IFERROR('Historical FS '!I107/'Historical FS '!I50,0) -> -1.1393426 | J42: =IFERROR('Historical FS '!J107/'Historical FS '!J50,0) -> 1.7706533 | ... L42: =IFERROR('Historical FS '!L107/'Historical FS '!L50,0) -> 1.683193 | N42: =IFERROR(AVERAGE(C42:L42),0) -> 2.4235447 | O42: =IFERROR(MEDIAN(C42:L42),0) -> 1.7319963

Sheet Common Size Statement
B2: ="Common Size Income Statement"&" "&"- "&'Data Sheet'!$B$1 -> Common Size Income Statement - ASIAN PAINTS LTD
B4: Particular | C4: ='Data Sheet'!B16 -> 42460 | D4: ='Data Sheet'!C16 -> 42825 | E4: ='Data Sheet'!D16 -> 43190 | F4: ='Data Sheet'!E16 -> 43555 | G4: ='Data Sheet'!F16 -> 43921 | H4: ='Data Sheet'!G16 -> 44286 | I4: ='Data Sheet'!H16 -> 44651 | J4: ='Data Sheet'!I16 -> 45016 | ... L4: ='Data Sheet'!K16 -> 45747
B6: ='Data Sheet'!A17 -> Sales | C6: ='Data Sheet'!B17/'Data Sheet'!B$17 -> 1 | D6: ='Data Sheet'!C17/'Data Sheet'!C$17 -> 1 | E6: ='Data Sheet'!D17/'Data Sheet'!D$17 -> 1 | F6: ='Data Sheet'!E17/'Data Sheet'!E$17 -> 1 | G6: ='Data Sheet'!F17/'Data Sheet'!F$17 -> 1 | H6: ='Data Sheet'!G17/'Data Sheet'!G$17 -> 1 | I6: ='Data Sheet'!H17/'Data Sheet'!H$17 -> 1 | J6: ='Data Sheet'!I17/'Data Sheet'!I$17 -> 1 | ... L6: ='Data Sheet'!K17/'Data Sheet'!K$17 -> 1
B7: ='Data Sheet'!A18 -> Raw Material Cost | C7: ='Data Sheet'!B18/'Data Sheet'!B$17 -> 0.46034647 | D7: ='Data Sheet'!C18/'Data Sheet'!C$17 -> 0.49479518 | E7: ='Data Sheet'!D18/'Data Sheet'!D$17 -> 0.48311366 | F7: ='Data Sheet'!E18/'Data Sheet'!E$17 -> 0.51841646 | G7: ='Data Sheet'!F18/'Data Sheet'!F$17 -> 0.49409067 | H7: ='Data Sheet'!G18/'Data Sheet'!G$17 -> 0.48015709 | I7: ='Data Sheet'!H18/'Data Sheet'!H$17 -> 0.58840195 | J7: ='Data Sheet'!I18/'Data Sheet'!I$17 -> 0.55048728 | ... L7: ='Data Sheet'!K18/'Data Sheet'!K$17 -> 0.51627164
B8: ='Data Sheet'!A19 -> Change in Inventory | C8: ='Data Sheet'!B19/'Data Sheet'!B$17 -> -0.013967007 | D8: ='Data Sheet'!C19/'Data Sheet'!C$17 -> 0.035094964 | E8: ='Data Sheet'!D19/'Data Sheet'!D$17 -> -0.0084477742 | F8: ='Data Sheet'!E19/'Data Sheet'!E$17 -> 0.015242101 | G8: ='Data Sheet'!F19/'Data Sheet'!F$17 -> 0.011832519 | H8: ='Data Sheet'!G19/'Data Sheet'!G$17 -> 0.0042578591 | I8: ='Data Sheet'!H19/'Data Sheet'!H$17 -> 0.045529612 | J8: ='Data Sheet'!I19/'Data Sheet'!I$17 -> 0.0089806513 | ... L8: ='Data Sheet'!K19/'Data Sheet'!K$17 -> 0.0060461953
B9: ='Data Sheet'!A20 -> Power and Fuel | C9: ='Data Sheet'!B20/'Data Sheet'!B$17 -> 0.0080215871 | D9: ='Data Sheet'!C20/'Data Sheet'!C$17 -> 0.0070389105 | E9: ='Data Sheet'!D20/'Data Sheet'!D$17 -> 0.006555896 | F9: ='Data Sheet'!E20/'Data Sheet'!E$17 -> 0.0062177335 | G9: ='Data Sheet'!F20/'Data Sheet'!F$17 -> 0.005686437 | H9: ='Data Sheet'!G20/'Data Sheet'!G$17 -> 0.0039631019 | I9: ='Data Sheet'!H20/'Data Sheet'!H$17 -> 0.0040283451 | J9: ='Data Sheet'!I20/'Data Sheet'!I$17 -> 0.0040097319 | ... L9: ='Data Sheet'!K20/'Data Sheet'!K$17 -> 0.0043821644
B10: ='Data Sheet'!A21 -> Other Mfr. Exp | C10: ='Data Sheet'!B21/'Data Sheet'!B$17 -> 0.10757251 | D10: ='Data Sheet'!C21/'Data Sheet'!C$17 -> 0.11039378 | E10: ='Data Sheet'!D21/'Data Sheet'!D$17 -> 0.10054831 | F10: ='Data Sheet'!E21/'Data Sheet'!E$17 -> 0.096795084 | G10: ='Data Sheet'!F21/'Data Sheet'!F$17 -> 0.096081143 | H10: ='Data Sheet'!G21/'Data Sheet'!G$17 -> 0.09525768 | I10: ='Data Sheet'!H21/'Data Sheet'!H$17 -> 0.098980182 | J10: ='Data Sheet'!I21/'Data Sheet'!I$17 -> 0.084555501 | ... L10: ='Data Sheet'!K21/'Data Sheet'!K$17 -> 0.079261196
B11: ='Data Sheet'!A22 -> Employee Cost | C11: ='Data Sheet'!B22/'Data Sheet'!B$17 -> 0.069718018 | D11: ='Data Sheet'!C22/'Data Sheet'!C$17 -> 0.069040678 | E11: ='Data Sheet'!D22/'Data Sheet'!D$17 -> 0.066681724 | F11: ='Data Sheet'!E22/'Data Sheet'!E$17 -> 0.064588441 | G11: ='Data Sheet'!F22/'Data Sheet'!F$17 -> 0.067846867 | H11: ='Data Sheet'!G22/'Data Sheet'!G$17 -> 0.071276423 | I11: ='Data Sheet'!H22/'Data Sheet'!H$17 -> 0.061667734 | J11: ='Data Sheet'!I22/'Data Sheet'!I$17 -> 0.059045905 | ... L11: ='Data Sheet'!K22/'Data Sheet'!K$17 -> 0.076853926
B12: ='Data Sheet'!A23 -> Selling and admin | C12: ='Data Sheet'!B23/'Data Sheet'!B$17 -> 0.27413396 | D12: ='Data Sheet'!C23/'Data Sheet'!C$17 -> 0.28973861 | E12: ='Data Sheet'!D23/'Data Sheet'!D$17 -> 0.13402558 | F12: ='Data Sheet'!E23/'Data Sheet'!E$17 -> 0.12301736 | G12: ='Data Sheet'!F23/'Data Sheet'!F$17 -> 0.12978663 | H12: ='Data Sheet'!G23/'Data Sheet'!G$17 -> 0.10342706 | I12: ='Data Sheet'!H23/'Data Sheet'!H$17 -> 0.10109452 | J12: ='Data Sheet'!I23/'Data Sheet'!I$17 -> 0.10150719 | ... L12: ='Data Sheet'!K23/'Data Sheet'!K$17 -> 0.11428607
B13: ='Data Sheet'!A24 -> Other Expenses | C13: ='Data Sheet'!B24/'Data Sheet'!B$17 -> -0.12470247 | D13: ='Data Sheet'!C24/'Data Sheet'!C$17 -> -0.13467477 | E13: ='Data Sheet'!D24/'Data Sheet'!D$17 -> 0.010190466 | F13: ='Data Sheet'!E24/'Data Sheet'!E$17 -> 0.010525397 | G13: ='Data Sheet'!F24/'Data Sheet'!F$17 -> 0.012149174 | H13: ='Data Sheet'!G24/'Data Sheet'!G$17 -> 0.026547947 | I13: ='Data Sheet'!H24/'Data Sheet'!H$17 -> 0.026291627 | J13: ='Data Sheet'!I24/'Data Sheet'!I$17 -> 0.027870377 | ... L13: ='Data Sheet'!K24/'Data Sheet'!K$17 -> 0.037846233
B14: ='Data Sheet'!A25 -> Other Income | C14: ='Data Sheet'!B25/'Data Sheet'!B$17 -> 0.014952188 | D14: ='Data Sheet'!C25/'Data Sheet'!C$17 -> 0.022433955 | E14: ='Data Sheet'!D25/'Data Sheet'!D$17 -> 0.019995186 | F14: ='Data Sheet'!E25/'Data Sheet'!E$17 -> 0.014229114 | G14: ='Data Sheet'!F25/'Data Sheet'!F$17 -> 0.017322036 | H14: ='Data Sheet'!G25/'Data Sheet'!G$17 -> 0.015274407 | I14: ='Data Sheet'!H25/'Data Sheet'!H$17 -> 0.01016725 | J14: ='Data Sheet'!I25/'Data Sheet'!I$17 -> 0.012510224 | ... L14: ='Data Sheet'!K25/'Data Sheet'!K$17 -> 0.010329261
B15: ='Data Sheet'!A26 -> Depreciation | C15: ='Data Sheet'!B26/'Data Sheet'!B$17 -> 0.019309827 | D15: ='Data Sheet'!C26/'Data Sheet'!C$17 -> 0.022227475 | E15: ='Data Sheet'!D26/'Data Sheet'!D$17 -> 0.021425239 | F15: ='Data Sheet'!E26/'Data Sheet'!E$17 -> 0.03233554 | G15: ='Data Sheet'!F26/'Data Sheet'!F$17 -> 0.038617107 | H15: ='Data Sheet'!G26/'Data Sheet'!G$17 -> 0.036442576 | I15: ='Data Sheet'!H26/'Data Sheet'!H$17 -> 0.028052374 | J15: ='Data Sheet'!I26/'Data Sheet'!I$17 -> 0.024878373 | ... L15: ='Data Sheet'!K26/'Data Sheet'!K$17 -> 0.030270498
B16: ='Data Sheet'!A27 -> Interest | C16: ='Data Sheet'!B27/'Data Sheet'!B$17 -> 0.0034334187 | D16: ='Data Sheet'!C27/'Data Sheet'!C$17 -> 0.0024784242 | E16: ='Data Sheet'!D27/'Data Sheet'!D$17 -> 0.0024648505 | F16: ='Data Sheet'!E27/'Data Sheet'!E$17 -> 0.0057416452 | G16: ='Data Sheet'!F27/'Data Sheet'!F$17 -> 0.0053410848 | H16: ='Data Sheet'!G27/'Data Sheet'!G$17 -> 0.0042200933 | I16: ='Data Sheet'!H27/'Data Sheet'!H$17 -> 0.0032785499 | J16: ='Data Sheet'!I27/'Data Sheet'!I$17 -> 0.0041883417 | ... L16: ='Data Sheet'!K27/'Data Sheet'!K$17 -> 0.0066956451
B17: ='Data Sheet'!A28 -> Profit before tax | C17: ='Data Sheet'!B28/'Data Sheet'!B$17 -> 0.18315186 | D17: ='Data Sheet'!C28/'Data Sheet'!C$17 -> 0.19649064 | E17: ='Data Sheet'!D28/'Data Sheet'!D$17 -> 0.18654169 | F17: ='Data Sheet'!E28/'Data Sheet'!E$17 -> 0.17183356 | G17: ='Data Sheet'!F28/'Data Sheet'!F$17 -> 0.17955545 | H17: ='Data Sheet'!G28/'Data Sheet'!G$17 -> 0.1982403 | I17: ='Data Sheet'!H28/'Data Sheet'!H$17 -> 0.14390157 | J17: ='Data Sheet'!I28/'Data Sheet'!I$17 -> 0.16494818 | ... L17: ='Data Sheet'!K28/'Data Sheet'!K$17 -> 0.15050809
... B20: ='Data Sheet'!A31 -> Dividend Amount | C20: ='Data Sheet'!B31/'Data Sheet'!B$17 -> 0.050408191 | D20: ='Data Sheet'!C31/'Data Sheet'!C$17 -> 0.065594254 | E20: ='Data Sheet'!D31/'Data Sheet'!D$17 -> 0.049600138 | F20: ='Data Sheet'!E31/'Data Sheet'!E$17 -> 0.05234684 | G20: ='Data Sheet'!F31/'Data Sheet'!F$17 -> 0.056950461 | H20: ='Data Sheet'!G31/'Data Sheet'!G$17 -> 0.078855366 | I20: ='Data Sheet'!H31/'Data Sheet'!H$17 -> 0.063119904 | J20: ='Data Sheet'!I31/'Data Sheet'!I$17 -> 0.071338086 | ... L20: ='Data Sheet'!K31/'Data Sheet'!K$17 -> 0.07016005
B21: ='Data Sheet'!A33 -> EBIDTA | C21: ='Data Sheet'!B33/'Data Sheet'!B$17 -> 0.20419942 | D21: ='Data Sheet'!C33/'Data Sheet'!C$17 -> 0.21609628 | E21: ='Data Sheet'!D33/'Data Sheet'!D$17 -> 0.20694937 | F21: ='Data Sheet'!E33/'Data Sheet'!E$17 -> 0.20720182 | G21: ='Data Sheet'!F33/'Data Sheet'!F$17 -> 0.22009871 | H21: ='Data Sheet'!G33/'Data Sheet'!G$17 -> 0.23579604 | I21: ='Data Sheet'!H33/'Data Sheet'!H$17 -> 0.17336866 | J21: ='Data Sheet'!I33/'Data Sheet'!I$17 -> 0.19143781 | ... L21: ='Data Sheet'!K33/'Data Sheet'!K$17 -> 0.18622134
B23: ="Common Size Balance Sheet"&" "&"- "&'Data Sheet'!$B$1 -> Common Size Balance Sheet - ASIAN PAINTS LTD
B25: Particular | C25: ='Data Sheet'!B56 -> 42460 | D25: ='Data Sheet'!C56 -> 42825 | E25: ='Data Sheet'!D56 -> 43190 | F25: ='Data Sheet'!E56 -> 43555 | G25: ='Data Sheet'!F56 -> 43921 | H25: ='Data Sheet'!G56 -> 44286 | I25: ='Data Sheet'!H56 -> 44651 | J25: ='Data Sheet'!I56 -> 45016 | ... L25: ='Data Sheet'!K56 -> 45747
B27: Total Laibilities | C27: ='Data Sheet'!B61/'Data Sheet'!B$61 -> 1 | D27: ='Data Sheet'!C61/'Data Sheet'!C$61 -> 1 | E27: ='Data Sheet'!D61/'Data Sheet'!D$61 -> 1 | F27: ='Data Sheet'!E61/'Data Sheet'!E$61 -> 1 | G27: ='Data Sheet'!F61/'Data Sheet'!F$61 -> 1 | H27: ='Data Sheet'!G61/'Data Sheet'!G$61 -> 1 | I27: ='Data Sheet'!H61/'Data Sheet'!H$61 -> 1 | J27: ='Data Sheet'!I61/'Data Sheet'!I$61 -> 1 | ... L27: ='Data Sheet'!K61/'Data Sheet'!K$61 -> 1
B28: ='Data Sheet'!A57 -> Equity Share Capital | C28: ='Data Sheet'!B57/'Data Sheet'!B$61 -> 0.0090841678 | D28: ='Data Sheet'!C57/'Data Sheet'!C$61 -> 0.0077322476 | E28: ='Data Sheet'!D57/'Data Sheet'!D$61 -> 0.0069691677 | F28: ='Data Sheet'!E57/'Data Sheet'!E$61 -> 0.0059031906 | G28: ='Data Sheet'!F57/'Data Sheet'!F$61 -> 0.0059437463 | H28: ='Data Sheet'!G57/'Data Sheet'!G$61 -> 0.004712277 | I28: ='Data Sheet'!H57/'Data Sheet'!H$61 -> 0.004177986 | J28: ='Data Sheet'!I57/'Data Sheet'!I$61 -> 0.0037208104 | ... L28: ='Data Sheet'!K57/'Data Sheet'!K$61 -> 0.0031599147
B29: ='Data Sheet'!A58 -> Reserves | C29: ='Data Sheet'!B58/'Data Sheet'!B$61 -> 0.60885328 | D29: ='Data Sheet'!C58/'Data Sheet'!C$61 -> 0.60522813 | E29: ='Data Sheet'!D58/'Data Sheet'!D$61 -> 0.60408487 | F29: ='Data Sheet'!E58/'Data Sheet'!E$61 -> 0.57694149 | G29: ='Data Sheet'!F58/'Data Sheet'!F$61 -> 0.62177833 | H29: ='Data Sheet'!G58/'Data Sheet'!G$61 -> 0.62442435 | I29: ='Data Sheet'!H58/'Data Sheet'!H$61 -> 0.59741193 | J29: ='Data Sheet'!I58/'Data Sheet'!I$61 -> 0.61663007 | ... L29: ='Data Sheet'!K58/'Data Sheet'!K$61 -> 0.6359325
B30: ='Data Sheet'!A59 -> Borrowings | C30: ='Data Sheet'!B59/'Data Sheet'!B$61 -> 0.030617396 | D30: ='Data Sheet'!C59/'Data Sheet'!C$61 -> 0.045169804 | E30: ='Data Sheet'!D59/'Data Sheet'!D$61 -> 0.038756913 | F30: ='Data Sheet'!E59/'Data Sheet'!E$61 -> 0.081211951 | G30: ='Data Sheet'!F59/'Data Sheet'!F$61 -> 0.069308593 | H30: ='Data Sheet'!G59/'Data Sheet'!G$61 -> 0.053701879 | I30: ='Data Sheet'!H59/'Data Sheet'!H$61 -> 0.069119709 | J30: ='Data Sheet'!I59/'Data Sheet'!I$61 -> 0.074967813 | ... L30: ='Data Sheet'!K59/'Data Sheet'!K$61 -> 0.075449552
B31: ='Data Sheet'!A60 -> Other Liabilities | C31: ='Data Sheet'!B60/'Data Sheet'!B$61 -> 0.35144516 | D31: ='Data Sheet'!C60/'Data Sheet'!C$61 -> 0.34186981 | E31: ='Data Sheet'!D60/'Data Sheet'!D$61 -> 0.35018905 | F31: ='Data Sheet'!E60/'Data Sheet'!E$61 -> 0.33594337 | G31: ='Data Sheet'!F60/'Data Sheet'!F$61 -> 0.30296933 | H31: ='Data Sheet'!G60/'Data Sheet'!G$61 -> 0.31716149 | I31: ='Data Sheet'!H60/'Data Sheet'!H$61 -> 0.32929037 | J31: ='Data Sheet'!I60/'Data Sheet'!I$61 -> 0.30468131 | ... L31: ='Data Sheet'!K60/'Data Sheet'!K$61 -> 0.28545803
B33: Total Assets | C33: ='Data Sheet'!B76/'Data Sheet'!B$76 -> 1 | D33: ='Data Sheet'!C76/'Data Sheet'!C$76 -> 1 | E33: ='Data Sheet'!D76/'Data Sheet'!D$76 -> 1 | F33: ='Data Sheet'!E76/'Data Sheet'!E$76 -> 1 | G33: ='Data Sheet'!F76/'Data Sheet'!F$76 -> 1 | H33: ='Data Sheet'!G76/'Data Sheet'!G$76 -> 1 | I33: ='Data Sheet'!H76/'Data Sheet'!H$76 -> 1 | J33: ='Data Sheet'!I76/'Data Sheet'!I$76 -> 1 | ... L33: ='Data Sheet'!K76/'Data Sheet'!K$76 -> 1
B34: ='Data Sheet'!A62 -> Net Block | C34: ='Data Sheet'!B62/'Data Sheet'!B$76 -> 0.32354771 | D34: ='Data Sheet'!C62/'Data Sheet'!C$76 -> 0.26631918 | E34: ='Data Sheet'!D62/'Data Sheet'!D$76 -> 0.27116979 | F34: ='Data Sheet'!E62/'Data Sheet'!E$76 -> 0.39981685 | G34: ='Data Sheet'!F62/'Data Sheet'!F$76 -> 0.38866784 | H34: ='Data Sheet'!G62/'Data Sheet'!G$76 -> 0.28781244 | I34: ='Data Sheet'!H62/'Data Sheet'!H$76 -> 0.24039362 | J34: ='Data Sheet'!I62/'Data Sheet'!I$76 -> 0.22384057 | ... L34: ='Data Sheet'!K62/'Data Sheet'!K$76 -> 0.30373988
B35: ='Data Sheet'!A63 -> Capital Work in Progress | C35: ='Data Sheet'!B63/'Data Sheet'!B$76 -> 0.010094677 | D35: ='Data Sheet'!C63/'Data Sheet'!C$76 -> 0.020760665 | E35: ='Data Sheet'!D63/'Data Sheet'!D$76 -> 0.10208973 | F35: ='Data Sheet'!E63/'Data Sheet'!E$76 -> 0.01290369 | G35: ='Data Sheet'!F63/'Data Sheet'!F$76 -> 0.0086900645 | H35: ='Data Sheet'!G63/'Data Sheet'!G$76 -> 0.0089892873 | I35: ='Data Sheet'!H63/'Data Sheet'!H$76 -> 0.018574005 | J35: ='Data Sheet'!I63/'Data Sheet'!I$76 -> 0.039550679 | ... L35: ='Data Sheet'!K63/'Data Sheet'!K$76 -> 0.041326953
B36: ='Data Sheet'!A64 -> Investments | C36: ='Data Sheet'!B64/'Data Sheet'!B$76 -> 0.25685409 | D36: ='Data Sheet'!C64/'Data Sheet'!C$76 -> 0.21378068 | E36: ='Data Sheet'!D64/'Data Sheet'!D$76 -> 0.15553479 | F36: ='Data Sheet'!E64/'Data Sheet'!E$76 -> 0.15807775 | G36: ='Data Sheet'!F64/'Data Sheet'!F$76 -> 0.12509938 | H36: ='Data Sheet'!G64/'Data Sheet'!G$76 -> 0.23270552 | I36: ='Data Sheet'!H64/'Data Sheet'!H$76 -> 0.14145262 | J36: ='Data Sheet'!I64/'Data Sheet'!I$76 -> 0.165315 | ... L36: ='Data Sheet'!K64/'Data Sheet'!K$76 -> 0.15564853
B37: ='Data Sheet'!A65 -> Other Assets | C37: ='Data Sheet'!B74/'Data Sheet'!B$76 -> 0.067688036 | D37: ='Data Sheet'!C74/'Data Sheet'!C$76 -> 0.10617895 | E37: ='Data Sheet'!D74/'Data Sheet'!D$76 -> 0.1229224 | F37: ='Data Sheet'!E74/'Data Sheet'!E$76 -> 0.09058862 | G37: ='Data Sheet'!F74/'Data Sheet'!F$76 -> 0.10774032 | H37: ='Data Sheet'!G74/'Data Sheet'!G$76 -> 0.12603671 | I37: ='Data Sheet'!H74/'Data Sheet'!H$76 -> 0.12529864 | J37: ='Data Sheet'!I74/'Data Sheet'!I$76 -> 0.11777536 | ... L37: ='Data Sheet'!K74/'Data Sheet'!K$76 -> 0.11006366
